Workbook

Sheet raw_data
A1: user_id | B1: signup_date | C1: experiment_group | D1: region | E1: device_type | F1: traffic_source | G1: plan_type | H1: visited_landing_page | I1: started_trial | J1: completed_onboarding | K1: converted_to_paid | L1: revenue_30d | M1: support_tickets_30d | N1: refund_requested | O1: days_to_convert | P1: engagement_score
A2: USR-100001 | B2: 45732 | C2: Control | D2: North | E2: Desktop | F2: Email | G2: Basic | H2: 0 | I2: 0 | J2: 0 | K2: 0 | L2: 0 | M2: 0 | N2: 0 | P2: 45.7
A3: USR-100002 | B3: 45724 | C3: Control | D3: West | E3: Mobile | F3: Organic | G3: Free | H3: 1 | I3: 0 | J3: 0 | K3: 0 | L3: 0 | M3: 0 | N3: 0 | P3: 48.6
A4: USR-100003 | B4: 45771 | C4: Control | D4: East | E4: Mobile | F4: Paid Search | G4: Premium | H4: 1 | I4: 0 | J4: 0 | K4: 0 | L4: 0 | M4: 1 | N4: 0 | P4: 35.4
A5: USR-100004 | B5: 45781 | C5: Control | D5: South | E5: Mobile | F5: Email | G5: Basic | H5: 1 | I5: 0 | J5: 0 | K5: 0 | L5: 0 | M5: 0 | N5: 0 | P5: 64.6
A6: USR-100005 | B6: 45700 | C6: Control | D6: North | E6: Tablet | F6: Organic | G6: Free | H6: 0 | I6: 0 | J6: 0 | K6: 0 | L6: 0 | M6: 0 | N6: 0 | P6: 66.6
A7: USR-100006 | B7: 45685 | C7: Control | D7: East | E7: Mobile | F7: Organic | G7: Premium | H7: 1 | I7: 0 | J7: 0 | K7: 0 | L7: 0 | M7: 0 | N7: 0 | P7: 40.8
A8: USR-100007 | B8: 45755 | C8: Control | D8: East | E8: Mobile | F8: Paid Search | G8: Basic | H8: 1 | I8: 1 | J8: 0 | K8: 0 | L8: 0 | M8: 0 | N8: 0 | P8: 57.1
A9: USR-100008 | B9: 45794 | C9: Control | D9: South | E9: Mobile | F9: Paid Search | G9: Free | H9: 0 | I9: 0 | J9: 0 | K9: 0 | L9: 0 | M9: 0 | N9: 0 | P9: 36.4
A10: USR-100009 | B10: 45711 | C10: Control | D10: South | E10: Tablet | F10: Referral | G10: Basic | H10: 0 | I10: 0 | J10: 0 | K10: 0 | L10: 0 | M10: 0 | N10: 0 | P10: 55.4
A11: USR-100010 | B11: 45806 | C11: Control | D11: West | E11: Desktop | F11: Social | G11: Free | H11: 1 | I11: 0 | J11: 0 | K11: 0 | L11: 0 | M11: 0 | N11: 0 | P11: 57.3
A12: USR-100011 | B12: 45777 | C12: Control | D12: East | E12: Mobile | F12: Paid Search | G12: Basic | H12: 1 | I12: 1 | J12: 1 | K12: 0 | L12: 0 | M12: 0 | N12: 0 | P12: 63.6
A13: USR-100012 | B13: 45732 | C13: Control | D13: East | E13: Mobile | F13: Social | G13: Premium | H13: 1 | I13: 1 | J13: 1 | K13: 0 | L13: 0 | M13: 1 | N13: 0 | P13: 80.4
... A60: USR-100059 | B60: 45761 | C60: Control | D60: North | E60: Mobile | F60: Social | G60: Free | H60: 0 | I60: 0 | J60: 0 | K60: 0 | L60: 0 | M60: 2 | N60: 0 | P60: 48.9
A61: USR-100060 | B61: 45658 | C61: Control | D61: West | E61: Mobile | F61: Social | G61: Free | H61: 1 | I61: 1 | J61: 1 | K61: 1 | L61: 240.42 | M61: 0 | N61: 0 | O61: 16 | P61: 56.5
A62: USR-100061 | B62: 45749 | C62: Control | D62: South | E62: Mobile | F62: Referral | G62: Free | H62: 1 | I62: 0 | J62: 0 | K62: 0 | L62: 0 | M62: 0 | N62: 0 | P62: 53.7
A63: USR-100062 | B63: 45745 | C63: Control | D63: North | E63: Mobile | F63: Social | G63: Premium | H63: 0 | I63: 0 | J63: 0 | K63: 0 | L63: 0 | M63: 0 | N63: 0 | P63: 62.2
A64: USR-100063 | B64: 45792 | C64: Control | D64: South | E64: Desktop | F64: Organic | G64: Free | H64: 1 | I64: 0 | J64: 0 | K64: 0 | L64: 0 | M64: 0 | N64: 0 | P64: 50.2
A65: USR-100064 | B65: 45758 | C65: Control | D65: North | E65: Mobile | F65: Organic | G65: Basic | H65: 1 | I65: 0 | J65: 0 | K65: 0 | L65: 0 | M65: 0 | N65: 0 | P65: 74.3
A66: USR-100065 | B66: 45723 | C66: Control | D66: South | E66: Desktop | F66: Paid Search | G66: Free | H66: 1 | I66: 0 | J66: 0 | K66: 0 | L66: 0 | M66: 0 | N66: 0 | P66: 58
A67: USR-100066 | B67: 45807 | C67: Control | D67: South | E67: Mobile | F67: Organic | G67: Free | H67: 0 | I67: 0 | J67: 0 | K67: 0 | L67: 0 | M67: 0 | N67: 0 | P67: 46.7
A68: USR-100067 | B68: 45664 | C68: Control | D68: South | E68: Desktop | F68: Organic | G68: Premium | H68: 1 | I68: 0 | J68: 0 | K68: 0 | L68: 0 | M68: 1 | N68: 0 | P68: 49.6
A69: USR-100068 | B69: 45785 | C69: Control | D69: West | E69: Mobile | F69: Social | G69: Free | H69: 0 | I69: 0 | J69: 0 | K69: 0 | L69: 0 | M69: 0 | N69: 0 | P69: 60.4
A70: USR-100069 | B70: 45735 | C70: Control | D70: East | E70: Desktop | F70: Email | G70: Free | H70: 1 | I70: 1 | J70: 1 | K70: 0 | L70: 0 | M70: 0 | N70: 0 | P70: 55.3
A71: USR-100070 | B71: 45793 | C71: Control | D71: North | E71: Desktop | F71: Organic | G71: Free | H71: 0 | I71: 0 | J71: 0 | K71: 0 | L71: 0 | M71: 0 | N71: 0 | P71: 56.2
A72: USR-100071 | B72: 45724 | C72: Control | D72: West | E72: Mobile | F72: Email | G72: Free | H72: 0 | I72: 0 | J72: 0 | K72: 0 | L72: 0 | M72: 0 | N72: 0 | P72: 29.4
A73: USR-100072 | B73: 45724 | C73: Control | D73: East | E73: Mobile | F73: Email | G73: Free | H73: 1 | I73: 0 | J73: 0 | K73: 0 | L73: 0 | M73: 0 | N73: 0 | P73: 54.2
... A79: USR-100078 | B79: 45673 | C79: Control | D79: North | E79: Mobile | F79: Organic | G79: Free | H79: 0 | I79: 0 | J79: 0 | K79: 0 | L79: 0 | M79: 2 | N79: 0 | P79: 48.4
A80: USR-100079 | B80: 45708 | C80: Control | D80: West | E80: Desktop | F80: Organic | G80: Free | H80: 1 | I80: 1 | J80: 1 | K80: 1 | L80: 457.51 | M80: 0 | N80: 0 | O80: 7 | P80: 38
A81: USR-100080 | B81: 45798 | C81: Control | D81: East | E81: Mobile | F81: Social | G81: Free | H81: 1 | I81: 0 | J81: 0 | K81: 0 | L81: 0 | M81: 0 | N81: 0 | P81: 44.2
A82: USR-100081 | B82: 45785 | C82: Control | D82: South | E82: Mobile | F82: Organic | G82: Free | H82: 1 | I82: 1 | J82: 1 | K82: 0 | L82: 0 | M82: 0 | N82: 0 | P82: 81.2
A83: USR-100082 | B83: 45724 | C83: Control | D83: South | E83: Mobile | F83: Referral | G83: Free | H83: 1 | I83: 1 | J83: 0 | K83: 0 | L83: 0 | M83: 0 | N83: 0 | P83: 63.8
A84: USR-100083 | B84: 45748 | C84: Control | D84: South | E84: Desktop | F84: Email | G84: Free | H84: 0 | I84: 0 | J84: 0 | K84: 0 | L84: 0 | M84: 0 | N84: 0 | P84: 64.7
A85: USR-100084 | B85: 45719 | C85: Control | D85: West | E85: Mobile | F85: Social | G85: Basic | H85: 0 | I85: 0 | J85: 0 | K85: 0 | L85: 0 | M85: 0 | N85: 0 | P85: 60.4
A86: USR-100085 | B86: 45763 | C86: Control | D86: South | E86: Mobile | F86: Paid Search | G86: Free | H86: 0 | I86: 0 | J86: 0 | K86: 0 | L86: 0 | M86: 0 | N86: 0 | P86: 66.6
A87: USR-100086 | B87: 45666 | C87: Control | D87: North | E87: Desktop | F87: Organic | G87: Free | H87: 1 | I87: 0 | J87: 0 | K87: 0 | L87: 0 | M87: 0 | N87: 0 | P87: 50.9
A88: USR-100087 | B88: 45679 | C88: Control | D88: West | E88: Desktop | F88: Social | G88: Basic | H88: 0 | I88: 0 | J88: 0 | K88: 0 | L88: 0 | M88: 0 | N88: 0 | P88: 51
A89: USR-100088 | B89: 45777 | C89: Control | D89: South | E89: Mobile | F89: Email | G89: Premium | H89: 0 | I89: 0 | J89: 0 | K89: 0 | L89: 0 | M89: 0 | N89: 0 | P89: 65.8
A90: USR-100089 | B90: 45772 | C90: Control | D90: North | E90: Mobile | F90: Referral | G90: Basic | H90: 1 | I90: 0 | J90: 0 | K90: 0 | L90: 0 | M90: 0 | N90: 0 | P90: 61.8
A91: USR-100090 | B91: 45689 | C91: Control | D91: North | E91: Mobile | F91: Organic | G91: Basic | H91: 1 | I91: 0 | J91: 0 | K91: 0 | L91: 0 | M91: 0 | N91: 0 | P91: 54.5
...

Sheet data_quality_checks
A1: Data Quality & Preparation Checks
A2: Source: raw_data sheet (campaign_experiment_data.xlsx, experiment_data tab)
A4: 1. Row Count
A5: Total rows in raw data | B5: =COUNTA(raw_data!A2:A100000) -> 1408
A7: 2. Missing Values by Column
A8: Column | B8: Missing Count | C8: Missing % | D8: Note
A9: user_id | B9: =COUNTBLANK(raw_data!A2:A1409) -> 0 | C9: =B9/COUNTA(raw_data!A2:A100000) -> 0
A10: signup_date | B10: =COUNTBLANK(raw_data!B2:B1409) -> 0 | C10: =B10/COUNTA(raw_data!A2:A100000) -> 0
A11: experiment_group | B11: =COUNTBLANK(raw_data!C2:C1409) -> 0 | C11: =B11/COUNTA(raw_data!A2:A100000) -> 0
A12: region | B12: =COUNTBLANK(raw_data!D2:D1409) -> 0 | C12: =B12/COUNTA(raw_data!A2:A100000) -> 0
A13: device_type | B13: =COUNTBLANK(raw_data!E2:E1409) -> 18 | C13: =B13/COUNTA(raw_data!A2:A100000) -> 0.012784091 | D13: Minor missingness; left as "Unknown" category, excluded from device-level % calcs
A14: traffic_source | B14: =COUNTBLANK(raw_data!F2:F1409) -> 24 | C14: =B14/COUNTA(raw_data!A2:A100000) -> 0.017045455 | D14: Minor missingness; left as "Unknown" category, excluded from source-level % calcs
A15: plan_type | B15: =COUNTBLANK(raw_data!G2:G1409) -> 0 | C15: =B15/COUNTA(raw_data!A2:A100000) -> 0
A16: visited_landing_page | B16: =COUNTBLANK(raw_data!H2:H1409) -> 0 | C16: =B16/COUNTA(raw_data!A2:A100000) -> 0
A17: started_trial | B17: =COUNTBLANK(raw_data!I2:I1409) -> 0 | C17: =B17/COUNTA(raw_data!A2:A100000) -> 0
A18: completed_onboarding | B18: =COUNTBLANK(raw_data!J2:J1409) -> 0 | C18: =B18/COUNTA(raw_data!A2:A100000) -> 0
A19: converted_to_paid | B19: =COUNTBLANK(raw_data!K2:K1409) -> 0 | C19: =B19/COUNTA(raw_data!A2:A100000) -> 0
A20: revenue_30d | B20: =COUNTBLANK(raw_data!L2:L1409) -> 0 | C20: =B20/COUNTA(raw_data!A2:A100000) -> 0
A21: support_tickets_30d | B21: =COUNTBLANK(raw_data!M2:M1409) -> 0 | C21: =B21/COUNTA(raw_data!A2:A100000) -> 0
A22: refund_requested | B22: =COUNTBLANK(raw_data!N2:N1409) -> 0 | C22: =B22/COUNTA(raw_data!A2:A100000) -> 0
A23: days_to_convert | B23: =COUNTBLANK(raw_data!O2:O1409) -> 1336 | C23: =B23/COUNTA(raw_data!A2:A100000) -> 0.94886364 | D23: Expected — NaN for every user who did NOT convert to paid (not missing data)
A24: engagement_score | B24: =COUNTBLANK(raw_data!P2:P1409) -> 14 | C24: =B24/COUNTA(raw_data!A2:A100000) -> 0.0099431818 | D24: Minor missingness; excluded via AVERAGE (ignores blanks) in summary calcs
A26: 3. Group Counts (experiment_group)
A27: Control | B27: =COUNTIF(raw_data!C2:C100000,"Control") -> 693
A28: Treatment | B28: =COUNTIF(raw_data!C2:C100000,"Treatment") -> 715
A29: Total | B29: =B27+B28 -> 1408
A31: 4. Duplicate User IDs
A32: Unique user_id count | B32: =SUMPRODUCT(1/COUNTIF(raw_data!A2:A1409,raw_data!A2:A1409)) -> 1400
A33: Duplicate rows found (total rows - unique IDs) | B33: =COUNTA(raw_data!A2:A100000)-B32 -> 8
A34: Handling | B34: 8 fully duplicated rows (4 user_ids x2) found and removed in cleaned_data sheet (kept first occurrence)
A36: 5. Invalid Binary Value Checks
A37: Column | B37: Values Found Outside {0,1} | C37: Note
A38: visited_landing_page | B38: =COUNTIFS(raw_data!H2:H1409,"<>0",raw_data!H2:H1409,"<>1") -> 0 | C38: Pass — only 0/1 values present
A39: started_trial | B39: =COUNTIFS(raw_data!I2:I1409,"<>0",raw_data!I2:I1409,"<>1") -> 0 | C39: Pass — only 0/1 values present
A40: completed_onboarding | B40: =COUNTIFS(raw_data!J2:J1409,"<>0",raw_data!J2:J1409,"<>1") -> 0 | C40: Pass — only 0/1 values present
A41: converted_to_paid | B41: =COUNTIFS(raw_data!K2:K1409,"<>0",raw_data!K2:K1409,"<>1") -> 0 | C41: Pass — only 0/1 values present
A42: refund_requested | B42: =COUNTIFS(raw_data!N2:N1409,"<>0",raw_data!N2:N1409,"<>1") -> 0 | C42: Pass — only 0/1 values present
A44: 6. Revenue Outlier Check (converted users only, IQR method)
A45: Q1 (25th pct) of revenue, converted users | B45: 404.02
A46: Q3 (75th pct) of revenue, converted users | B46: 1178.665
...

Sheet cleaned_data
A1: user_id | B1: signup_date | C1: experiment_group | D1: region | E1: device_type | F1: traffic_source | G1: plan_type | H1: visited_landing_page | I1: started_trial | J1: completed_onboarding | K1: converted_to_paid | L1: revenue_30d | M1: support_tickets_30d | N1: refund_requested | O1: days_to_convert | P1: engagement_score | Q1: engagement_control_only | R1: engagement_treatment_only | S1: revenue_control_converted | T1: revenue_treatment_converted
A2: USR-100001 | B2: 45732 | C2: Control | D2: North | E2: Desktop | F2: Email | G2: Basic | H2: 0 | I2: 0 | J2: 0 | K2: 0 | L2: 0 | M2: 0 | N2: 0 | P2: 45.7 | Q2: =IF($C2="Control",$P2,"") -> 45.7 | R2: =IF($C2="Treatment",$P2,"") | S2: =IF(AND($C2="Control",$K2=1),$L2,"") | T2: =IF(AND($C2="Treatment",$K2=1),$L2,"")
A3: USR-100002 | B3: 45724 | C3: Control | D3: West | E3: Mobile | F3: Organic | G3: Free | H3: 1 | I3: 0 | J3: 0 | K3: 0 | L3: 0 | M3: 0 | N3: 0 | P3: 48.6 | Q3: =IF($C3="Control",$P3,"") -> 48.6 | R3: =IF($C3="Treatment",$P3,"") | S3: =IF(AND($C3="Control",$K3=1),$L3,"") | T3: =IF(AND($C3="Treatment",$K3=1),$L3,"")
A4: USR-100003 | B4: 45771 | C4: Control | D4: East | E4: Mobile | F4: Paid Search | G4: Premium | H4: 1 | I4: 0 | J4: 0 | K4: 0 | L4: 0 | M4: 1 | N4: 0 | P4: 35.4 | Q4: =IF($C4="Control",$P4,"") -> 35.4 | R4: =IF($C4="Treatment",$P4,"") | S4: =IF(AND($C4="Control",$K4=1),$L4,"") | T4: =IF(AND($C4="Treatment",$K4=1),$L4,"")
A5: USR-100004 | B5: 45781 | C5: Control | D5: South | E5: Mobile | F5: Email | G5: Basic | H5: 1 | I5: 0 | J5: 0 | K5: 0 | L5: 0 | M5: 0 | N5: 0 | P5: 64.6 | Q5: =IF($C5="Control",$P5,"") -> 64.6 | R5: =IF($C5="Treatment",$P5,"") | S5: =IF(AND($C5="Control",$K5=1),$L5,"") | T5: =IF(AND($C5="Treatment",$K5=1),$L5,"")
A6: USR-100005 | B6: 45700 | C6: Control | D6: North | E6: Tablet | F6: Organic | G6: Free | H6: 0 | I6: 0 | J6: 0 | K6: 0 | L6: 0 | M6: 0 | N6: 0 | P6: 66.6 | Q6: =IF($C6="Control",$P6,"") -> 66.6 | R6: =IF($C6="Treatment",$P6,"") | S6: =IF(AND($C6="Control",$K6=1),$L6,"") | T6: =IF(AND($C6="Treatment",$K6=1),$L6,"")
A7: USR-100006 | B7: 45685 | C7: Control | D7: East | E7: Mobile | F7: Organic | G7: Premium | H7: 1 | I7: 0 | J7: 0 | K7: 0 | L7: 0 | M7: 0 | N7: 0 | P7: 40.8 | Q7: =IF($C7="Control",$P7,"") -> 40.8 | R7: =IF($C7="Treatment",$P7,"") | S7: =IF(AND($C7="Control",$K7=1),$L7,"") | T7: =IF(AND($C7="Treatment",$K7=1),$L7,"")
A8: USR-100007 | B8: 45755 | C8: Control | D8: East | E8: Mobile | F8: Paid Search | G8: Basic | H8: 1 | I8: 1 | J8: 0 | K8: 0 | L8: 0 | M8: 0 | N8: 0 | P8: 57.1 | Q8: =IF($C8="Control",$P8,"") -> 57.1 | R8: =IF($C8="Treatment",$P8,"") | S8: =IF(AND($C8="Control",$K8=1),$L8,"") | T8: =IF(AND($C8="Treatment",$K8=1),$L8,"")
A9: USR-100008 | B9: 45794 | C9: Control | D9: South | E9: Mobile | F9: Paid Search | G9: Free | H9: 0 | I9: 0 | J9: 0 | K9: 0 | L9: 0 | M9: 0 | N9: 0 | P9: 36.4 | Q9: =IF($C9="Control",$P9,"") -> 36.4 | R9: =IF($C9="Treatment",$P9,"") | S9: =IF(AND($C9="Control",$K9=1),$L9,"") | T9: =IF(AND($C9="Treatment",$K9=1),$L9,"")
A10: USR-100009 | B10: 45711 | C10: Control | D10: South | E10: Tablet | F10: Referral | G10: Basic | H10: 0 | I10: 0 | J10: 0 | K10: 0 | L10: 0 | M10: 0 | N10: 0 | P10: 55.4 | Q10: =IF($C10="Control",$P10,"") -> 55.4 | R10: =IF($C10="Treatment",$P10,"") | S10: =IF(AND($C10="Control",$K10=1),$L10,"") | T10: =IF(AND($C10="Treatment",$K10=1),$L10,"")
A11: USR-100010 | B11: 45806 | C11: Control | D11: West | E11: Desktop | F11: Social | G11: Free | H11: 1 | I11: 0 | J11: 0 | K11: 0 | L11: 0 | M11: 0 | N11: 0 | P11: 57.3 | Q11: =IF($C11="Control",$P11,"") -> 57.3 | R11: =IF($C11="Treatment",$P11,"") | S11: =IF(AND($C11="Control",$K11=1),$L11,"") | T11: =IF(AND($C11="Treatment",$K11=1),$L11,"")
A12: USR-100011 | B12: 45777 | C12: Control | D12: East | E12: Mobile | F12: Paid Search | G12: Basic | H12: 1 | I12: 1 | J12: 1 | K12: 0 | L12: 0 | M12: 0 | N12: 0 | P12: 63.6 | Q12: =IF($C12="Control",$P12,"") -> 63.6 | R12: =IF($C12="Treatment",$P12,"") | S12: =IF(AND($C12="Control",$K12=1),$L12,"") | T12: =IF(AND($C12="Treatment",$K12=1),$L12,"")
A13: USR-100012 | B13: 45732 | C13: Control | D13: East | E13: Mobile | F13: Social | G13: Premium | H13: 1 | I13: 1 | J13: 1 | K13: 0 | L13: 0 | M13: 1 | N13: 0 | P13: 80.4 | Q13: =IF($C13="Control",$P13,"") -> 80.4 | R13: =IF($C13="Treatment",$P13,"") | S13: =IF(AND($C13="Control",$K13=1),$L13,"") | T13: =IF(AND($C13="Treatment",$K13=1),$L13,"")
... A60: USR-100059 | B60: 45761 | C60: Control | D60: North | E60: Mobile | F60: Social | G60: Free | H60: 0 | I60: 0 | J60: 0 | K60: 0 | L60: 0 | M60: 2 | N60: 0 | P60: 48.9 | Q60: =IF($C60="Control",$P60,"") -> 48.9 | R60: =IF($C60="Treatment",$P60,"") | S60: =IF(AND($C60="Control",$K60=1),$L60,"") | T60: =IF(AND($C60="Treatment",$K60=1),$L60,"")
A61: USR-100060 | B61: 45658 | C61: Control | D61: West | E61: Mobile | F61: Social | G61: Free | H61: 1 | I61: 1 | J61: 1 | K61: 1 | L61: 240.42 | M61: 0 | N61: 0 | O61: 16 | P61: 56.5 | Q61: =IF($C61="Control",$P61,"") -> 56.5 | R61: =IF($C61="Treatment",$P61,"") | S61: =IF(AND($C61="Control",$K61=1),$L61,"") -> 240.42 | T61: =IF(AND($C61="Treatment",$K61=1),$L61,"")
A62: USR-100061 | B62: 45749 | C62: Control | D62: South | E62: Mobile | F62: Referral | G62: Free | H62: 1 | I62: 0 | J62: 0 | K62: 0 | L62: 0 | M62: 0 | N62: 0 | P62: 53.7 | Q62: =IF($C62="Control",$P62,"") -> 53.7 | R62: =IF($C62="Treatment",$P62,"") | S62: =IF(AND($C62="Control",$K62=1),$L62,"") | T62: =IF(AND($C62="Treatment",$K62=1),$L62,"")
A63: USR-100062 | B63: 45745 | C63: Control | D63: North | E63: Mobile | F63: Social | G63: Premium | H63: 0 | I63: 0 | J63: 0 | K63: 0 | L63: 0 | M63: 0 | N63: 0 | P63: 62.2 | Q63: =IF($C63="Control",$P63,"") -> 62.2 | R63: =IF($C63="Treatment",$P63,"") | S63: =IF(AND($C63="Control",$K63=1),$L63,"") | T63: =IF(AND($C63="Treatment",$K63=1),$L63,"")
A64: USR-100063 | B64: 45792 | C64: Control | D64: South | E64: Desktop | F64: Organic | G64: Free | H64: 1 | I64: 0 | J64: 0 | K64: 0 | L64: 0 | M64: 0 | N64: 0 | P64: 50.2 | Q64: =IF($C64="Control",$P64,"") -> 50.2 | R64: =IF($C64="Treatment",$P64,"") | S64: =IF(AND($C64="Control",$K64=1),$L64,"") | T64: =IF(AND($C64="Treatment",$K64=1),$L64,"")
A65: USR-100064 | B65: 45758 | C65: Control | D65: North | E65: Mobile | F65: Organic | G65: Basic | H65: 1 | I65: 0 | J65: 0 | K65: 0 | L65: 0 | M65: 0 | N65: 0 | P65: 74.3 | Q65: =IF($C65="Control",$P65,"") -> 74.3 | R65: =IF($C65="Treatment",$P65,"") | S65: =IF(AND($C65="Control",$K65=1),$L65,"") | T65: =IF(AND($C65="Treatment",$K65=1),$L65,"")
A66: USR-100065 | B66: 45723 | C66: Control | D66: South | E66: Desktop | F66: Paid Search | G66: Free | H66: 1 | I66: 0 | J66: 0 | K66: 0 | L66: 0 | M66: 0 | N66: 0 | P66: 58 | Q66: =IF($C66="Control",$P66,"") -> 58 | R66: =IF($C66="Treatment",$P66,"") | S66: =IF(AND($C66="Control",$K66=1),$L66,"") | T66: =IF(AND($C66="Treatment",$K66=1),$L66,"")
A67: USR-100066 | B67: 45807 | C67: Control | D67: South | E67: Mobile | F67: Organic | G67: Free | H67: 0 | I67: 0 | J67: 0 | K67: 0 | L67: 0 | M67: 0 | N67: 0 | P67: 46.7 | Q67: =IF($C67="Control",$P67,"") -> 46.7 | R67: =IF($C67="Treatment",$P67,"") | S67: =IF(AND($C67="Control",$K67=1),$L67,"") | T67: =IF(AND($C67="Treatment",$K67=1),$L67,"")
A68: USR-100067 | B68: 45664 | C68: Control | D68: South | E68: Desktop | F68: Organic | G68: Premium | H68: 1 | I68: 0 | J68: 0 | K68: 0 | L68: 0 | M68: 1 | N68: 0 | P68: 49.6 | Q68: =IF($C68="Control",$P68,"") -> 49.6 | R68: =IF($C68="Treatment",$P68,"") | S68: =IF(AND($C68="Control",$K68=1),$L68,"") | T68: =IF(AND($C68="Treatment",$K68=1),$L68,"")
A69: USR-100068 | B69: 45785 | C69: Control | D69: West | E69: Mobile | F69: Social | G69: Free | H69: 0 | I69: 0 | J69: 0 | K69: 0 | L69: 0 | M69: 0 | N69: 0 | P69: 60.4 | Q69: =IF($C69="Control",$P69,"") -> 60.4 | R69: =IF($C69="Treatment",$P69,"") | S69: =IF(AND($C69="Control",$K69=1),$L69,"") | T69: =IF(AND($C69="Treatment",$K69=1),$L69,"")
A70: USR-100069 | B70: 45735 | C70: Control | D70: East | E70: Desktop | F70: Email | G70: Free | H70: 1 | I70: 1 | J70: 1 | K70: 0 | L70: 0 | M70: 0 | N70: 0 | P70: 55.3 | Q70: =IF($C70="Control",$P70,"") -> 55.3 | R70: =IF($C70="Treatment",$P70,"") | S70: =IF(AND($C70="Control",$K70=1),$L70,"") | T70: =IF(AND($C70="Treatment",$K70=1),$L70,"")
A71: USR-100070 | B71: 45793 | C71: Control | D71: North | E71: Desktop | F71: Organic | G71: Free | H71: 0 | I71: 0 | J71: 0 | K71: 0 | L71: 0 | M71: 0 | N71: 0 | P71: 56.2 | Q71: =IF($C71="Control",$P71,"") -> 56.2 | R71: =IF($C71="Treatment",$P71,"") | S71: =IF(AND($C71="Control",$K71=1),$L71,"") | T71: =IF(AND($C71="Treatment",$K71=1),$L71,"")
A72: USR-100071 | B72: 45724 | C72: Control | D72: West | E72: Mobile | F72: Email | G72: Free | H72: 0 | I72: 0 | J72: 0 | K72: 0 | L72: 0 | M72: 0 | N72: 0 | P72: 29.4 | Q72: =IF($C72="Control",$P72,"") -> 29.4 | R72: =IF($C72="Treatment",$P72,"") | S72: =IF(AND($C72="Control",$K72=1),$L72,"") | T72: =IF(AND($C72="Treatment",$K72=1),$L72,"")
A73: USR-100072 | B73: 45724 | C73: Control | D73: East | E73: Mobile | F73: Email | G73: Free | H73: 1 | I73: 0 | J73: 0 | K73: 0 | L73: 0 | M73: 0 | N73: 0 | P73: 54.2 | Q73: =IF($C73="Control",$P73,"") -> 54.2 | R73: =IF($C73="Treatment",$P73,"") | S73: =IF(AND($C73="Control",$K73=1),$L73,"") | T73: =IF(AND($C73="Treatment",$K73=1),$L73,"")
... A79: USR-100078 | B79: 45673 | C79: Control | D79: North | E79: Mobile | F79: Organic | G79: Free | H79: 0 | I79: 0 | J79: 0 | K79: 0 | L79: 0 | M79: 2 | N79: 0 | P79: 48.4 | Q79: =IF($C79="Control",$P79,"") -> 48.4 | R79: =IF($C79="Treatment",$P79,"") | S79: =IF(AND($C79="Control",$K79=1),$L79,"") | T79: =IF(AND($C79="Treatment",$K79=1),$L79,"")
A80: USR-100079 | B80: 45708 | C80: Control | D80: West | E80: Desktop | F80: Organic | G80: Free | H80: 1 | I80: 1 | J80: 1 | K80: 1 | L80: 457.51 | M80: 0 | N80: 0 | O80: 7 | P80: 38 | Q80: =IF($C80="Control",$P80,"") -> 38 | R80: =IF($C80="Treatment",$P80,"") | S80: =IF(AND($C80="Control",$K80=1),$L80,"") -> 457.51 | T80: =IF(AND($C80="Treatment",$K80=1),$L80,"")
A81: USR-100080 | B81: 45798 | C81: Control | D81: East | E81: Mobile | F81: Social | G81: Free | H81: 1 | I81: 0 | J81: 0 | K81: 0 | L81: 0 | M81: 0 | N81: 0 | P81: 44.2 | Q81: =IF($C81="Control",$P81,"") -> 44.2 | R81: =IF($C81="Treatment",$P81,"") | S81: =IF(AND($C81="Control",$K81=1),$L81,"") | T81: =IF(AND($C81="Treatment",$K81=1),$L81,"")
A82: USR-100081 | B82: 45785 | C82: Control | D82: South | E82: Mobile | F82: Organic | G82: Free | H82: 1 | I82: 1 | J82: 1 | K82: 0 | L82: 0 | M82: 0 | N82: 0 | P82: 81.2 | Q82: =IF($C82="Control",$P82,"") -> 81.2 | R82: =IF($C82="Treatment",$P82,"") | S82: =IF(AND($C82="Control",$K82=1),$L82,"") | T82: =IF(AND($C82="Treatment",$K82=1),$L82,"")
A83: USR-100082 | B83: 45724 | C83: Control | D83: South | E83: Mobile | F83: Referral | G83: Free | H83: 1 | I83: 1 | J83: 0 | K83: 0 | L83: 0 | M83: 0 | N83: 0 | P83: 63.8 | Q83: =IF($C83="Control",$P83,"") -> 63.8 | R83: =IF($C83="Treatment",$P83,"") | S83: =IF(AND($C83="Control",$K83=1),$L83,"") | T83: =IF(AND($C83="Treatment",$K83=1),$L83,"")
A84: USR-100083 | B84: 45748 | C84: Control | D84: South | E84: Desktop | F84: Email | G84: Free | H84: 0 | I84: 0 | J84: 0 | K84: 0 | L84: 0 | M84: 0 | N84: 0 | P84: 64.7 | Q84: =IF($C84="Control",$P84,"") -> 64.7 | R84: =IF($C84="Treatment",$P84,"") | S84: =IF(AND($C84="Control",$K84=1),$L84,"") | T84: =IF(AND($C84="Treatment",$K84=1),$L84,"")
A85: USR-100084 | B85: 45719 | C85: Control | D85: West | E85: Mobile | F85: Social | G85: Basic | H85: 0 | I85: 0 | J85: 0 | K85: 0 | L85: 0 | M85: 0 | N85: 0 | P85: 60.4 | Q85: =IF($C85="Control",$P85,"") -> 60.4 | R85: =IF($C85="Treatment",$P85,"") | S85: =IF(AND($C85="Control",$K85=1),$L85,"") | T85: =IF(AND($C85="Treatment",$K85=1),$L85,"")
A86: USR-100085 | B86: 45763 | C86: Control | D86: South | E86: Mobile | F86: Paid Search | G86: Free | H86: 0 | I86: 0 | J86: 0 | K86: 0 | L86: 0 | M86: 0 | N86: 0 | P86: 66.6 | Q86: =IF($C86="Control",$P86,"") -> 66.6 | R86: =IF($C86="Treatment",$P86,"") | S86: =IF(AND($C86="Control",$K86=1),$L86,"") | T86: =IF(AND($C86="Treatment",$K86=1),$L86,"")
A87: USR-100086 | B87: 45666 | C87: Control | D87: North | E87: Desktop | F87: Organic | G87: Free | H87: 1 | I87: 0 | J87: 0 | K87: 0 | L87: 0 | M87: 0 | N87: 0 | P87: 50.9 | Q87: =IF($C87="Control",$P87,"") -> 50.9 | R87: =IF($C87="Treatment",$P87,"") | S87: =IF(AND($C87="Control",$K87=1),$L87,"") | T87: =IF(AND($C87="Treatment",$K87=1),$L87,"")
A88: USR-100087 | B88: 45679 | C88: Control | D88: West | E88: Desktop | F88: Social | G88: Basic | H88: 0 | I88: 0 | J88: 0 | K88: 0 | L88: 0 | M88: 0 | N88: 0 | P88: 51 | Q88: =IF($C88="Control",$P88,"") -> 51 | R88: =IF($C88="Treatment",$P88,"") | S88: =IF(AND($C88="Control",$K88=1),$L88,"") | T88: =IF(AND($C88="Treatment",$K88=1),$L88,"")
A89: USR-100088 | B89: 45777 | C89: Control | D89: South | E89: Mobile | F89: Email | G89: Premium | H89: 0 | I89: 0 | J89: 0 | K89: 0 | L89: 0 | M89: 0 | N89: 0 | P89: 65.8 | Q89: =IF($C89="Control",$P89,"") -> 65.8 | R89: =IF($C89="Treatment",$P89,"") | S89: =IF(AND($C89="Control",$K89=1),$L89,"") | T89: =IF(AND($C89="Treatment",$K89=1),$L89,"")
A90: USR-100089 | B90: 45772 | C90: Control | D90: North | E90: Mobile | F90: Referral | G90: Basic | H90: 1 | I90: 0 | J90: 0 | K90: 0 | L90: 0 | M90: 0 | N90: 0 | P90: 61.8 | Q90: =IF($C90="Control",$P90,"") -> 61.8 | R90: =IF($C90="Treatment",$P90,"") | S90: =IF(AND($C90="Control",$K90=1),$L90,"") | T90: =IF(AND($C90="Treatment",$K90=1),$L90,"")
A91: USR-100090 | B91: 45689 | C91: Control | D91: North | E91: Mobile | F91: Organic | G91: Basic | H91: 1 | I91: 0 | J91: 0 | K91: 0 | L91: 0 | M91: 0 | N91: 0 | P91: 54.5 | Q91: =IF($C91="Control",$P91,"") -> 54.5 | R91: =IF($C91="Treatment",$P91,"") | S91: =IF(AND($C91="Control",$K91=1),$L91,"") | T91: =IF(AND($C91="Treatment",$K91=1),$L91,"")
...

Sheet segment_balance
A1: Segment Distribution Across Control vs Treatment (Randomization Check)
A2: Similar % shares between groups confirm balanced random assignment.
A4: Region
A5: region | B5: Control n | C5: Treatment n | D5: Control % | E5: Treatment %
A6: East | B6: =COUNTIFS(cleaned_data!$D$2:$D$1401,A6,cleaned_data!$C$2:$C$1401,"Control") -> 157 | C6: =COUNTIFS(cleaned_data!$D$2:$D$1401,A6,cleaned_data!$C$2:$C$1401,"Treatment") -> 170 | D6: =B6/SUM($B$6:$B$9) -> 0.22753623 | E6: =C6/SUM($C$6:$C$9) -> 0.23943662
A7: North | B7: =COUNTIFS(cleaned_data!$D$2:$D$1401,A7,cleaned_data!$C$2:$C$1401,"Control") -> 201 | C7: =COUNTIFS(cleaned_data!$D$2:$D$1401,A7,cleaned_data!$C$2:$C$1401,"Treatment") -> 180 | D7: =B7/SUM($B$6:$B$9) -> 0.29130435 | E7: =C7/SUM($C$6:$C$9) -> 0.25352113
A8: South | B8: =COUNTIFS(cleaned_data!$D$2:$D$1401,A8,cleaned_data!$C$2:$C$1401,"Control") -> 184 | C8: =COUNTIFS(cleaned_data!$D$2:$D$1401,A8,cleaned_data!$C$2:$C$1401,"Treatment") -> 183 | D8: =B8/SUM($B$6:$B$9) -> 0.26666667 | E8: =C8/SUM($C$6:$C$9) -> 0.25774648
A9: West | B9: =COUNTIFS(cleaned_data!$D$2:$D$1401,A9,cleaned_data!$C$2:$C$1401,"Control") -> 148 | C9: =COUNTIFS(cleaned_data!$D$2:$D$1401,A9,cleaned_data!$C$2:$C$1401,"Treatment") -> 177 | D9: =B9/SUM($B$6:$B$9) -> 0.21449275 | E9: =C9/SUM($C$6:$C$9) -> 0.24929577
A12: Device Type
A13: device_type | B13: Control n | C13: Treatment n | D13: Control % | E13: Treatment %
A14: Desktop | B14: =COUNTIFS(cleaned_data!$E$2:$E$1401,A14,cleaned_data!$C$2:$C$1401,"Control") -> 200 | C14: =COUNTIFS(cleaned_data!$E$2:$E$1401,A14,cleaned_data!$C$2:$C$1401,"Treatment") -> 213 | D14: =B14/SUM($B$14:$B$17) -> 0.28985507 | E14: =C14/SUM($C$14:$C$17) -> 0.3
A15: Mobile | B15: =COUNTIFS(cleaned_data!$E$2:$E$1401,A15,cleaned_data!$C$2:$C$1401,"Control") -> 426 | C15: =COUNTIFS(cleaned_data!$E$2:$E$1401,A15,cleaned_data!$C$2:$C$1401,"Treatment") -> 432 | D15: =B15/SUM($B$14:$B$17) -> 0.6173913 | E15: =C15/SUM($C$14:$C$17) -> 0.6084507
A16: Tablet | B16: =COUNTIFS(cleaned_data!$E$2:$E$1401,A16,cleaned_data!$C$2:$C$1401,"Control") -> 55 | C16: =COUNTIFS(cleaned_data!$E$2:$E$1401,A16,cleaned_data!$C$2:$C$1401,"Treatment") -> 56 | D16: =B16/SUM($B$14:$B$17) -> 0.079710145 | E16: =C16/SUM($C$14:$C$17) -> 0.078873239
A17: Unknown | B17: =COUNTIFS(cleaned_data!$E$2:$E$1401,A17,cleaned_data!$C$2:$C$1401,"Control") -> 9 | C17: =COUNTIFS(cleaned_data!$E$2:$E$1401,A17,cleaned_data!$C$2:$C$1401,"Treatment") -> 9 | D17: =B17/SUM($B$14:$B$17) -> 0.013043478 | E17: =C17/SUM($C$14:$C$17) -> 0.012676056
A20: Traffic Source
A21: traffic_source | B21: Control n | C21: Treatment n | D21: Control % | E21: Treatment %
A22: Email | B22: =COUNTIFS(cleaned_data!$F$2:$F$1401,A22,cleaned_data!$C$2:$C$1401,"Control") -> 73 | C22: =COUNTIFS(cleaned_data!$F$2:$F$1401,A22,cleaned_data!$C$2:$C$1401,"Treatment") -> 56 | D22: =B22/SUM($B$22:$B$27) -> 0.1057971 | E22: =C22/SUM($C$22:$C$27) -> 0.078873239
A23: Organic | B23: =COUNTIFS(cleaned_data!$F$2:$F$1401,A23,cleaned_data!$C$2:$C$1401,"Control") -> 246 | C23: =COUNTIFS(cleaned_data!$F$2:$F$1401,A23,cleaned_data!$C$2:$C$1401,"Treatment") -> 237 | D23: =B23/SUM($B$22:$B$27) -> 0.35652174 | E23: =C23/SUM($C$22:$C$27) -> 0.33380282
A24: Paid Search | B24: =COUNTIFS(cleaned_data!$F$2:$F$1401,A24,cleaned_data!$C$2:$C$1401,"Control") -> 155 | C24: =COUNTIFS(cleaned_data!$F$2:$F$1401,A24,cleaned_data!$C$2:$C$1401,"Treatment") -> 176 | D24: =B24/SUM($B$22:$B$27) -> 0.22463768 | E24: =C24/SUM($C$22:$C$27) -> 0.24788732
A25: Referral | B25: =COUNTIFS(cleaned_data!$F$2:$F$1401,A25,cleaned_data!$C$2:$C$1401,"Control") -> 81 | C25: =COUNTIFS(cleaned_data!$F$2:$F$1401,A25,cleaned_data!$C$2:$C$1401,"Treatment") -> 91 | D25: =B25/SUM($B$22:$B$27) -> 0.1173913 | E25: =C25/SUM($C$22:$C$27) -> 0.12816901
A26: Social | B26: =COUNTIFS(cleaned_data!$F$2:$F$1401,A26,cleaned_data!$C$2:$C$1401,"Control") -> 129 | C26: =COUNTIFS(cleaned_data!$F$2:$F$1401,A26,cleaned_data!$C$2:$C$1401,"Treatment") -> 132 | D26: =B26/SUM($B$22:$B$27) -> 0.18695652 | E26: =C26/SUM($C$22:$C$27) -> 0.18591549
A27: Unknown | B27: =COUNTIFS(cleaned_data!$F$2:$F$1401,A27,cleaned_data!$C$2:$C$1401,"Control") -> 6 | C27: =COUNTIFS(cleaned_data!$F$2:$F$1401,A27,cleaned_data!$C$2:$C$1401,"Treatment") -> 18 | D27: =B27/SUM($B$22:$B$27) -> 0.0086956522 | E27: =C27/SUM($C$22:$C$27) -> 0.025352113
A30: Plan Type
A31: plan_type | B31: Control n | C31: Treatment n | D31: Control % | E31: Treatment %
A32: Basic | B32: =COUNTIFS(cleaned_data!$G$2:$G$1401,A32,cleaned_data!$C$2:$C$1401,"Control") -> 221 | C32: =COUNTIFS(cleaned_data!$G$2:$G$1401,A32,cleaned_data!$C$2:$C$1401,"Treatment") -> 232 | D32: =B32/SUM($B$32:$B$34) -> 0.32028986 | E32: =C32/SUM($C$32:$C$34) -> 0.32676056
A33: Free | B33: =COUNTIFS(cleaned_data!$G$2:$G$1401,A33,cleaned_data!$C$2:$C$1401,"Control") -> 360 | C33: =COUNTIFS(cleaned_data!$G$2:$G$1401,A33,cleaned_data!$C$2:$C$1401,"Treatment") -> 366 | D33: =B33/SUM($B$32:$B$34) -> 0.52173913 | E33: =C33/SUM($C$32:$C$34) -> 0.51549296
A34: Premium | B34: =COUNTIFS(cleaned_data!$G$2:$G$1401,A34,cleaned_data!$C$2:$C$1401,"Control") -> 109 | C34: =COUNTIFS(cleaned_data!$G$2:$G$1401,A34,cleaned_data!$C$2:$C$1401,"Treatment") -> 112 | D34: =B34/SUM($B$32:$B$34) -> 0.15797101 | E34: =C34/SUM($C$32:$C$34) -> 0.15774648

Sheet metrics_summary
A1: Experiment Metrics Summary — Control vs Treatment
A2: All values computed via live formulas referencing cleaned_data (duplicates removed).
A4: Metric | B4: Control | C4: Treatment | D4: Absolute Diff | E4: Relative Lift %
A5: User count | B5: =COUNTIF(cleaned_data!$C$2:$C$1401,"Control") -> 690 | C5: =COUNTIF(cleaned_data!$C$2:$C$1401,"Treatment") -> 710 | D5: =C5-B5 -> 20 | E5: =IF(B5=0,"n/a",(C5-B5)/B5) -> 0.028985507
A6: Landing page visit rate | B6: =AVERAGEIF(cleaned_data!$C$2:$C$1401,"Control",cleaned_data!$H$2:$H$1401) -> 0.63623188 | C6: =AVERAGEIF(cleaned_data!$C$2:$C$1401,"Treatment",cleaned_data!$H$2:$H$1401) -> 0.72394366 | D6: =C6-B6 -> 0.087711778 | E6: =IF(B6=0,"n/a",(C6-B6)/B6) -> 0.13786134
A7: Trial start rate | B7: =AVERAGEIF(cleaned_data!$C$2:$C$1401,"Control",cleaned_data!$I$2:$I$1401) -> 0.25072464 | C7: =AVERAGEIF(cleaned_data!$C$2:$C$1401,"Treatment",cleaned_data!$I$2:$I$1401) -> 0.29014085 | D7: =C7-B7 -> 0.039416207 | E7: =IF(B7=0,"n/a",(C7-B7)/B7) -> 0.15720915
A8: Onboarding completion rate | B8: =AVERAGEIF(cleaned_data!$C$2:$C$1401,"Control",cleaned_data!$J$2:$J$1401) -> 0.15652174 | C8: =AVERAGEIF(cleaned_data!$C$2:$C$1401,"Treatment",cleaned_data!$J$2:$J$1401) -> 0.21126761 | D8: =C8-B8 -> 0.054745867 | E8: =IF(B8=0,"n/a",(C8-B8)/B8) -> 0.34976526
A9: Paid conversion rate (North Star) | B9: =AVERAGEIF(cleaned_data!$C$2:$C$1401,"Control",cleaned_data!$K$2:$K$1401) -> 0.031884058 | C9: =AVERAGEIF(cleaned_data!$C$2:$C$1401,"Treatment",cleaned_data!$K$2:$K$1401) -> 0.070422535 | D9: =C9-B9 -> 0.038538477 | E9: =IF(B9=0,"n/a",(C9-B9)/B9) -> 1.2087068
A10: Average revenue per user | B10: =AVERAGEIF(cleaned_data!$C$2:$C$1401,"Control",cleaned_data!$L$2:$L$1401) -> 51.974319 | C10: =AVERAGEIF(cleaned_data!$C$2:$C$1401,"Treatment",cleaned_data!$L$2:$L$1401) -> 54.254521 | D10: =C10-B10 -> 2.2802023 | E10: =IF(B10=0,"n/a",(C10-B10)/B10) -> 0.043871711
A11: Average revenue per converted user | B11: =AVERAGEIFS(cleaned_data!$L$2:$L$1401,cleaned_data!$C$2:$C$1401,"Control",cleaned_data!$K$2:$K$1401,1) -> 1630.1036 | C11: =AVERAGEIFS(cleaned_data!$L$2:$L$1401,cleaned_data!$C$2:$C$1401,"Treatment",cleaned_data!$K$2:$K$1401,1) -> 770.4142 | D11: =C11-B11 -> -859.68944 | E11: =IF(B11=0,"n/a",(C11-B11)/B11) -> -0.5273833
A12: Refund rate | B12: =AVERAGEIF(cleaned_data!$C$2:$C$1401,"Control",cleaned_data!$N$2:$N$1401) -> 0 | C12: =AVERAGEIF(cleaned_data!$C$2:$C$1401,"Treatment",cleaned_data!$N$2:$N$1401) -> 0.0042253521 | D12: =C12-B12 -> 0.0042253521 | E12: =IF(B12=0,"n/a",(C12-B12)/B12) -> n/a
A13: Support ticket rate (any ticket) | B13: =COUNTIFS(cleaned_data!$C$2:$C$1401,"Control",cleaned_data!$M$2:$M$1401,">0")/COUNTIF(cleaned_data!$C$2:$C$1401,"Control") -> 0.14782609 | C13: =COUNTIFS(cleaned_data!$C$2:$C$1401,"Treatment",cleaned_data!$M$2:$M$1401,">0")/COUNTIF(cleaned_data!$C$2:$C$1401,"Treatment") -> 0.24788732 | D13: =C13-B13 -> 0.10006124 | E13: =IF(B13=0,"n/a",(C13-B13)/B13) -> 0.67688484
A14: Average engagement score | B14: =AVERAGEIF(cleaned_data!$C$2:$C$1401,"Control",cleaned_data!$P$2:$P$1401) -> 57.029532 | C14: =AVERAGEIF(cleaned_data!$C$2:$C$1401,"Treatment",cleaned_data!$P$2:$P$1401) -> 62.940028 | D14: =C14-B14 -> 5.9104963 | E14: =IF(B14=0,"n/a",(C14-B14)/B14) -> 0.10363922
A15: Average days to convert (converted users) | B15: =AVERAGEIFS(cleaned_data!$O$2:$O$1401,cleaned_data!$C$2:$C$1401,"Control",cleaned_data!$K$2:$K$1401,1) -> 8.8636364 | C15: =AVERAGEIFS(cleaned_data!$O$2:$O$1401,cleaned_data!$C$2:$C$1401,"Treatment",cleaned_data!$K$2:$K$1401,1) -> 6.4 | D15: =C15-B15 -> -2.4636364 | E15: =IF(B15=0,"n/a",(C15-B15)/B15) -> -0.27794872

Sheet segment_metrics
A1: Metrics by Segment — Region, Device Type, Plan Type
A2: Required: at least 3 metrics analyzed by segment. Shown here: paid conversion rate, refund rate, average engagement score.
A4: Region
A5: region | B5: Group | C5: N | D5: Conversion Rate | E5: Refund Rate | F5: Avg Engagement Score
A6: East | B6: Control | C6: =COUNTIFS(cleaned_data!$D$2:$D$1401,"East",cleaned_data!$C$2:$C$1401,"Control") -> 157 | D6: =AVERAGEIFS(cleaned_data!$K$2:$K$1401,cleaned_data!$D$2:$D$1401,"East",cleaned_data!$C$2:$C$1401,"Control") -> 0.025477707 | E6: =AVERAGEIFS(cleaned_data!$N$2:$N$1401,cleaned_data!$D$2:$D$1401,"East",cleaned_data!$C$2:$C$1401,"Control") -> 0 | F6: =AVERAGEIFS(cleaned_data!$P$2:$P$1401,cleaned_data!$D$2:$D$1401,"East",cleaned_data!$C$2:$C$1401,"Control") -> 56.556051
A7: East | B7: Treatment | C7: =COUNTIFS(cleaned_data!$D$2:$D$1401,"East",cleaned_data!$C$2:$C$1401,"Treatment") -> 170 | D7: =AVERAGEIFS(cleaned_data!$K$2:$K$1401,cleaned_data!$D$2:$D$1401,"East",cleaned_data!$C$2:$C$1401,"Treatment") -> 0.064705882 | E7: =AVERAGEIFS(cleaned_data!$N$2:$N$1401,cleaned_data!$D$2:$D$1401,"East",cleaned_data!$C$2:$C$1401,"Treatment") -> 0.0058823529 | F7: =AVERAGEIFS(cleaned_data!$P$2:$P$1401,cleaned_data!$D$2:$D$1401,"East",cleaned_data!$C$2:$C$1401,"Treatment") -> 63.307692
A8: North | B8: Control | C8: =COUNTIFS(cleaned_data!$D$2:$D$1401,"North",cleaned_data!$C$2:$C$1401,"Control") -> 201 | D8: =AVERAGEIFS(cleaned_data!$K$2:$K$1401,cleaned_data!$D$2:$D$1401,"North",cleaned_data!$C$2:$C$1401,"Control") -> 0.034825871 | E8: =AVERAGEIFS(cleaned_data!$N$2:$N$1401,cleaned_data!$D$2:$D$1401,"North",cleaned_data!$C$2:$C$1401,"Control") -> 0 | F8: =AVERAGEIFS(cleaned_data!$P$2:$P$1401,cleaned_data!$D$2:$D$1401,"North",cleaned_data!$C$2:$C$1401,"Control") -> 57.616667
A9: North | B9: Treatment | C9: =COUNTIFS(cleaned_data!$D$2:$D$1401,"North",cleaned_data!$C$2:$C$1401,"Treatment") -> 180 | D9: =AVERAGEIFS(cleaned_data!$K$2:$K$1401,cleaned_data!$D$2:$D$1401,"North",cleaned_data!$C$2:$C$1401,"Treatment") -> 0.088888889 | E9: =AVERAGEIFS(cleaned_data!$N$2:$N$1401,cleaned_data!$D$2:$D$1401,"North",cleaned_data!$C$2:$C$1401,"Treatment") -> 0 | F9: =AVERAGEIFS(cleaned_data!$P$2:$P$1401,cleaned_data!$D$2:$D$1401,"North",cleaned_data!$C$2:$C$1401,"Treatment") -> 63.153977
A10: South | B10: Control | C10: =COUNTIFS(cleaned_data!$D$2:$D$1401,"South",cleaned_data!$C$2:$C$1401,"Control") -> 184 | D10: =AVERAGEIFS(cleaned_data!$K$2:$K$1401,cleaned_data!$D$2:$D$1401,"South",cleaned_data!$C$2:$C$1401,"Control") -> 0.032608696 | E10: =AVERAGEIFS(cleaned_data!$N$2:$N$1401,cleaned_data!$D$2:$D$1401,"South",cleaned_data!$C$2:$C$1401,"Control") -> 0 | F10: =AVERAGEIFS(cleaned_data!$P$2:$P$1401,cleaned_data!$D$2:$D$1401,"South",cleaned_data!$C$2:$C$1401,"Control") -> 56.904972
A11: South | B11: Treatment | C11: =COUNTIFS(cleaned_data!$D$2:$D$1401,"South",cleaned_data!$C$2:$C$1401,"Treatment") -> 183 | D11: =AVERAGEIFS(cleaned_data!$K$2:$K$1401,cleaned_data!$D$2:$D$1401,"South",cleaned_data!$C$2:$C$1401,"Treatment") -> 0.076502732 | E11: =AVERAGEIFS(cleaned_data!$N$2:$N$1401,cleaned_data!$D$2:$D$1401,"South",cleaned_data!$C$2:$C$1401,"Treatment") -> 0 | F11: =AVERAGEIFS(cleaned_data!$P$2:$P$1401,cleaned_data!$D$2:$D$1401,"South",cleaned_data!$C$2:$C$1401,"Treatment") -> 62.11326
A12: West | B12: Control | C12: =COUNTIFS(cleaned_data!$D$2:$D$1401,"West",cleaned_data!$C$2:$C$1401,"Control") -> 148 | D12: =AVERAGEIFS(cleaned_data!$K$2:$K$1401,cleaned_data!$D$2:$D$1401,"West",cleaned_data!$C$2:$C$1401,"Control") -> 0.033783784 | E12: =AVERAGEIFS(cleaned_data!$N$2:$N$1401,cleaned_data!$D$2:$D$1401,"West",cleaned_data!$C$2:$C$1401,"Control") -> 0 | F12: =AVERAGEIFS(cleaned_data!$P$2:$P$1401,cleaned_data!$D$2:$D$1401,"West",cleaned_data!$C$2:$C$1401,"Control") -> 56.898649
A13: West | B13: Treatment | C13: =COUNTIFS(cleaned_data!$D$2:$D$1401,"West",cleaned_data!$C$2:$C$1401,"Treatment") -> 177 | D13: =AVERAGEIFS(cleaned_data!$K$2:$K$1401,cleaned_data!$D$2:$D$1401,"West",cleaned_data!$C$2:$C$1401,"Treatment") -> 0.050847458 | E13: =AVERAGEIFS(cleaned_data!$N$2:$N$1401,cleaned_data!$D$2:$D$1401,"West",cleaned_data!$C$2:$C$1401,"Treatment") -> 0.011299435 | F13: =AVERAGEIFS(cleaned_data!$P$2:$P$1401,cleaned_data!$D$2:$D$1401,"West",cleaned_data!$C$2:$C$1401,"Treatment") -> 63.223295
A15: Device Type
A16: device_type | B16: Group | C16: N | D16: Conversion Rate | E16: Refund Rate | F16: Avg Engagement Score
A17: Desktop | B17: Control | C17: =COUNTIFS(cleaned_data!$E$2:$E$1401,"Desktop",cleaned_data!$C$2:$C$1401,"Control") -> 200 | D17: =AVERAGEIFS(cleaned_data!$K$2:$K$1401,cleaned_data!$E$2:$E$1401,"Desktop",cleaned_data!$C$2:$C$1401,"Control") -> 0.045 | E17: =AVERAGEIFS(cleaned_data!$N$2:$N$1401,cleaned_data!$E$2:$E$1401,"Desktop",cleaned_data!$C$2:$C$1401,"Control") -> 0 | F17: =AVERAGEIFS(cleaned_data!$P$2:$P$1401,cleaned_data!$E$2:$E$1401,"Desktop",cleaned_data!$C$2:$C$1401,"Control") -> 57.212563
A18: Desktop | B18: Treatment | C18: =COUNTIFS(cleaned_data!$E$2:$E$1401,"Desktop",cleaned_data!$C$2:$C$1401,"Treatment") -> 213 | D18: =AVERAGEIFS(cleaned_data!$K$2:$K$1401,cleaned_data!$E$2:$E$1401,"Desktop",cleaned_data!$C$2:$C$1401,"Treatment") -> 0.0657277 | E18: =AVERAGEIFS(cleaned_data!$N$2:$N$1401,cleaned_data!$E$2:$E$1401,"Desktop",cleaned_data!$C$2:$C$1401,"Treatment") -> 0 | F18: =AVERAGEIFS(cleaned_data!$P$2:$P$1401,cleaned_data!$E$2:$E$1401,"Desktop",cleaned_data!$C$2:$C$1401,"Treatment") -> 63.210427
A19: Mobile | B19: Control | C19: =COUNTIFS(cleaned_data!$E$2:$E$1401,"Mobile",cleaned_data!$C$2:$C$1401,"Control") -> 426 | D19: =AVERAGEIFS(cleaned_data!$K$2:$K$1401,cleaned_data!$E$2:$E$1401,"Mobile",cleaned_data!$C$2:$C$1401,"Control") -> 0.025821596 | E19: =AVERAGEIFS(cleaned_data!$N$2:$N$1401,cleaned_data!$E$2:$E$1401,"Mobile",cleaned_data!$C$2:$C$1401,"Control") -> 0 | F19: =AVERAGEIFS(cleaned_data!$P$2:$P$1401,cleaned_data!$E$2:$E$1401,"Mobile",cleaned_data!$C$2:$C$1401,"Control") -> 57.363981
A20: Mobile | B20: Treatment | C20: =COUNTIFS(cleaned_data!$E$2:$E$1401,"Mobile",cleaned_data!$C$2:$C$1401,"Treatment") -> 432 | D20: =AVERAGEIFS(cleaned_data!$K$2:$K$1401,cleaned_data!$E$2:$E$1401,"Mobile",cleaned_data!$C$2:$C$1401,"Treatment") -> 0.074074074 | E20: =AVERAGEIFS(cleaned_data!$N$2:$N$1401,cleaned_data!$E$2:$E$1401,"Mobile",cleaned_data!$C$2:$C$1401,"Treatment") -> 0.0069444444 | F20: =AVERAGEIFS(cleaned_data!$P$2:$P$1401,cleaned_data!$E$2:$E$1401,"Mobile",cleaned_data!$C$2:$C$1401,"Treatment") -> 62.813615
A21: Tablet | B21: Control | C21: =COUNTIFS(cleaned_data!$E$2:$E$1401,"Tablet",cleaned_data!$C$2:$C$1401,"Control") -> 55 | D21: =AVERAGEIFS(cleaned_data!$K$2:$K$1401,cleaned_data!$E$2:$E$1401,"Tablet",cleaned_data!$C$2:$C$1401,"Control") -> 0.018181818 | E21: =AVERAGEIFS(cleaned_data!$N$2:$N$1401,cleaned_data!$E$2:$E$1401,"Tablet",cleaned_data!$C$2:$C$1401,"Control") -> 0 | F21: =AVERAGEIFS(cleaned_data!$P$2:$P$1401,cleaned_data!$E$2:$E$1401,"Tablet",cleaned_data!$C$2:$C$1401,"Control") -> 55.662963
A22: Tablet | B22: Treatment | C22: =COUNTIFS(cleaned_data!$E$2:$E$1401,"Tablet",cleaned_data!$C$2:$C$1401,"Treatment") -> 56 | D22: =AVERAGEIFS(cleaned_data!$K$2:$K$1401,cleaned_data!$E$2:$E$1401,"Tablet",cleaned_data!$C$2:$C$1401,"Treatment") -> 0.071428571 | E22: =AVERAGEIFS(cleaned_data!$N$2:$N$1401,cleaned_data!$E$2:$E$1401,"Tablet",cleaned_data!$C$2:$C$1401,"Treatment") -> 0 | F22: =AVERAGEIFS(cleaned_data!$P$2:$P$1401,cleaned_data!$E$2:$E$1401,"Tablet",cleaned_data!$C$2:$C$1401,"Treatment") -> 63.007143
A23: Unknown | B23: Control | C23: =COUNTIFS(cleaned_data!$E$2:$E$1401,"Unknown",cleaned_data!$C$2:$C$1401,"Control") -> 9 | D23: =AVERAGEIFS(cleaned_data!$K$2:$K$1401,cleaned_data!$E$2:$E$1401,"Unknown",cleaned_data!$C$2:$C$1401,"Control") -> 0.11111111 | E23: =AVERAGEIFS(cleaned_data!$N$2:$N$1401,cleaned_data!$E$2:$E$1401,"Unknown",cleaned_data!$C$2:$C$1401,"Control") -> 0 | F23: =AVERAGEIFS(cleaned_data!$P$2:$P$1401,cleaned_data!$E$2:$E$1401,"Unknown",cleaned_data!$C$2:$C$1401,"Control") -> 45.5
A24: Unknown | B24: Treatment | C24: =COUNTIFS(cleaned_data!$E$2:$E$1401,"Unknown",cleaned_data!$C$2:$C$1401,"Treatment") -> 9 | D24: =AVERAGEIFS(cleaned_data!$K$2:$K$1401,cleaned_data!$E$2:$E$1401,"Unknown",cleaned_data!$C$2:$C$1401,"Treatment") -> 0 | E24: =AVERAGEIFS(cleaned_data!$N$2:$N$1401,cleaned_data!$E$2:$E$1401,"Unknown",cleaned_data!$C$2:$C$1401,"Treatment") -> 0 | F24: =AVERAGEIFS(cleaned_data!$P$2:$P$1401,cleaned_data!$E$2:$E$1401,"Unknown",cleaned_data!$C$2:$C$1401,"Treatment") -> 62.166667
A26: Plan Type
A27: plan_type | B27: Group | C27: N | D27: Conversion Rate | E27: Refund Rate | F27: Avg Engagement Score
A28: Basic | B28: Control | C28: =COUNTIFS(cleaned_data!$G$2:$G$1401,"Basic",cleaned_data!$C$2:$C$1401,"Control") -> 221 | D28: =AVERAGEIFS(cleaned_data!$K$2:$K$1401,cleaned_data!$G$2:$G$1401,"Basic",cleaned_data!$C$2:$C$1401,"Control") -> 0.036199095 | E28: =AVERAGEIFS(cleaned_data!$N$2:$N$1401,cleaned_data!$G$2:$G$1401,"Basic",cleaned_data!$C$2:$C$1401,"Control") -> 0 | F28: =AVERAGEIFS(cleaned_data!$P$2:$P$1401,cleaned_data!$G$2:$G$1401,"Basic",cleaned_data!$C$2:$C$1401,"Control") -> 56.970455
A29: Basic | B29: Treatment | C29: =COUNTIFS(cleaned_data!$G$2:$G$1401,"Basic",cleaned_data!$C$2:$C$1401,"Treatment") -> 232 | D29: =AVERAGEIFS(cleaned_data!$K$2:$K$1401,cleaned_data!$G$2:$G$1401,"Basic",cleaned_data!$C$2:$C$1401,"Treatment") -> 0.038793103 | E29: =AVERAGEIFS(cleaned_data!$N$2:$N$1401,cleaned_data!$G$2:$G$1401,"Basic",cleaned_data!$C$2:$C$1401,"Treatment") -> 0 | F29: =AVERAGEIFS(cleaned_data!$P$2:$P$1401,cleaned_data!$G$2:$G$1401,"Basic",cleaned_data!$C$2:$C$1401,"Treatment") -> 62.996087
A30: Free | B30: Control | C30: =COUNTIFS(cleaned_data!$G$2:$G$1401,"Free",cleaned_data!$C$2:$C$1401,"Control") -> 360 | D30: =AVERAGEIFS(cleaned_data!$K$2:$K$1401,cleaned_data!$G$2:$G$1401,"Free",cleaned_data!$C$2:$C$1401,"Control") -> 0.030555556 | E30: =AVERAGEIFS(cleaned_data!$N$2:$N$1401,cleaned_data!$G$2:$G$1401,"Free",cleaned_data!$C$2:$C$1401,"Control") -> 0 | F30: =AVERAGEIFS(cleaned_data!$P$2:$P$1401,cleaned_data!$G$2:$G$1401,"Free",cleaned_data!$C$2:$C$1401,"Control") -> 57.257183
A31: Free | B31: Treatment | C31: =COUNTIFS(cleaned_data!$G$2:$G$1401,"Free",cleaned_data!$C$2:$C$1401,"Treatment") -> 366 | D31: =AVERAGEIFS(cleaned_data!$K$2:$K$1401,cleaned_data!$G$2:$G$1401,"Free",cleaned_data!$C$2:$C$1401,"Treatment") -> 0.092896175 | E31: =AVERAGEIFS(cleaned_data!$N$2:$N$1401,cleaned_data!$G$2:$G$1401,"Free",cleaned_data!$C$2:$C$1401,"Treatment") -> 0.0054644809 | F31: =AVERAGEIFS(cleaned_data!$P$2:$P$1401,cleaned_data!$G$2:$G$1401,"Free",cleaned_data!$C$2:$C$1401,"Treatment") -> 62.204144
A32: Premium | B32: Control | C32: =COUNTIFS(cleaned_data!$G$2:$G$1401,"Premium",cleaned_data!$C$2:$C$1401,"Control") -> 109 | D32: =AVERAGEIFS(cleaned_data!$K$2:$K$1401,cleaned_data!$G$2:$G$1401,"Premium",cleaned_data!$C$2:$C$1401,"Control") -> 0.027522936 | E32: =AVERAGEIFS(cleaned_data!$N$2:$N$1401,cleaned_data!$G$2:$G$1401,"Premium",cleaned_data!$C$2:$C$1401,"Control") -> 0 | F32: =AVERAGEIFS(cleaned_data!$P$2:$P$1401,cleaned_data!$G$2:$G$1401,"Premium",cleaned_data!$C$2:$C$1401,"Control") -> 56.407339
A33: Premium | B33: Treatment | C33: =COUNTIFS(cleaned_data!$G$2:$G$1401,"Premium",cleaned_data!$C$2:$C$1401,"Treatment") -> 112 | D33: =AVERAGEIFS(cleaned_data!$K$2:$K$1401,cleaned_data!$G$2:$G$1401,"Premium",cleaned_data!$C$2:$C$1401,"Treatment") -> 0.0625 | E33: =AVERAGEIFS(cleaned_data!$N$2:$N$1401,cleaned_data!$G$2:$G$1401,"Premium",cleaned_data!$C$2:$C$1401,"Treatment") -> 0.0089285714 | F33: =AVERAGEIFS(cleaned_data!$P$2:$P$1401,cleaned_data!$G$2:$G$1401,"Premium",cleaned_data!$C$2:$C$1401,"Treatment") -> 65.244545

Sheet hypothesis_testing
A1: Hypothesis Testing — Two-Proportion Z-Tests & T-Tests
A2: H0: no difference between Control and Treatment. Significance threshold: alpha = 0.05.
A4: A. Primary Metric — Paid Conversion Rate (Two-Proportion Z-Test)
A6: Control conversions (x1) | B6: =SUMIF(cleaned_data!$C$2:$C$1401,"Control",cleaned_data!$K$2:$K$1401) -> 22
A7: Control n (n1) | B7: =COUNTIF(cleaned_data!$C$2:$C$1401,"Control") -> 690
A8: Treatment conversions (x2) | B8: =SUMIF(cleaned_data!$C$2:$C$1401,"Treatment",cleaned_data!$K$2:$K$1401) -> 50
A9: Treatment n (n2) | B9: =COUNTIF(cleaned_data!$C$2:$C$1401,"Treatment") -> 710
A10: p1 = x1/n1 | B10: =B6/B7 -> 0.031884058
A11: p2 = x2/n2 | B11: =B8/B9 -> 0.070422535
A12: Pooled proportion | B12: =(B6+B8)/(B7+B9) -> 0.051428571
A13: Standard error | B13: =SQRT(B12*(1-B12)*(1/B7+1/B9)) -> 0.011807217
A14: Z statistic | B14: =(B11-B10)/B13 -> 3.2639763
A15: P-value (two-tailed) | B15: =2*(1-_xlfn.NORM.S.DIST(ABS(B14),TRUE())) -> 0.0010986034
A16: Significant at alpha=0.05? | B16: =IF(B15<0.05,"YES - Significant","No") -> YES - Significant
A17: Relative lift (p2-p1)/p1 | B17: =(B11-B10)/B10 -> 1.2087068
A19: B. Guardrail — Refund Rate (Two-Proportion Z-Test)
A21: Control refunds (x1) | B21: =SUMIF(cleaned_data!$C$2:$C$1401,"Control",cleaned_data!$N$2:$N$1401) -> 0
A22: Control n (n1) | B22: =COUNTIF(cleaned_data!$C$2:$C$1401,"Control") -> 690
A23: Treatment refunds (x2) | B23: =SUMIF(cleaned_data!$C$2:$C$1401,"Treatment",cleaned_data!$N$2:$N$1401) -> 3
A24: Treatment n (n2) | B24: =COUNTIF(cleaned_data!$C$2:$C$1401,"Treatment") -> 710
A25: p1 | B25: =B21/B22 -> 0
A26: p2 | B26: =B23/B24 -> 0.0042253521
A27: Pooled proportion | B27: =(B21+B23)/(B22+B24) -> 0.0021428571
A28: Standard error | B28: =SQRT(B27*(1-B27)*(1/B22+1/B24)) -> 0.002471958
A29: Z statistic | B29: =IF(B28=0,"n/a",(B26-B25)/B28) -> 1.7093139
A30: P-value (two-tailed) | B30: =IF(ISNUMBER(B29),2*(1-_xlfn.NORM.S.DIST(ABS(B29),TRUE())),"n/a") -> 0.087392828
A31: Significant at alpha=0.05? | B31: =IF(ISNUMBER(B30),IF(B30<0.05,"YES - Significant","No"),"n/a") -> No
A33: C. Guardrail — Support Ticket Rate (Two-Proportion Z-Test)
A35: Control users w/ >=1 ticket (x1) | B35: =COUNTIFS(cleaned_data!$C$2:$C$1401,"Control",cleaned_data!$M$2:$M$1401,">0") -> 102
A36: Control n (n1) | B36: =COUNTIF(cleaned_data!$C$2:$C$1401,"Control") -> 690
A37: Treatment users w/ >=1 ticket (x2) | B37: =COUNTIFS(cleaned_data!$C$2:$C$1401,"Treatment",cleaned_data!$M$2:$M$1401,">0") -> 176
A38: Treatment n (n2) | B38: =COUNTIF(cleaned_data!$C$2:$C$1401,"Treatment") -> 710
A39: p1 | B39: =B35/B36 -> 0.14782609
A40: p2 | B40: =B37/B38 -> 0.24788732
A41: Pooled proportion | B41: =(B35+B37)/(B36+B38) -> 0.19857143
A42: Standard error | B42: =SQRT(B41*(1-B41)*(1/B36+1/B38)) -> 0.021325592
A43: Z statistic | B43: =(B40-B39)/B42 -> 4.6920732
A44: P-value (two-tailed) | B44: =2*(1-_xlfn.NORM.S.DIST(ABS(B43),TRUE())) -> 2.7045032e-06
A45: Significant at alpha=0.05? | B45: =IF(B44<0.05,"YES - Significant","No") -> YES - Significant
A47: D. Engagement Score — Welch t-test (unequal variance)
...
